Workbook

Sheet Overview
B2: CRESTVIEW | D2: DASHBOARD OVERVIEW | K2: =Calc!$C$8 -> Full year 2025 | M2: Year | N2: 2025 | P2: Month | Q2: All
B3: RETAIL CO.
E4: TOTAL SALES | I4: TOTAL PROFIT | M4: TOTAL ORDERS | Q4: TOTAL CUSTOMERS
D5: $ | E5: =Calc!C12 -> 146335 | H5: ▮▮ | I5: =Calc!C13 -> 81660 | L5: ◫ | M5: =Calc!C14 -> 1514 | P5: ☺ | Q5: =Calc!C15 -> 448
B6: =HYPERLINK("#'Overview'!A1","⌂") -> ⌂ | E6: =IF(OR(NOT(Calc!$C$9),Calc!D12=0),"No earlier data",IF(Calc!C12>=Calc!D12,"↑ ","↓ ")&TEXT(ABS(Calc!C12/Calc!D12-1),"0.0%")&" vs "&Calc!$C$7) -> ↑ 8.7% vs 2024 | I6: =IF(OR(NOT(Calc!$C$9),Calc!D13=0),"No earlier data",IF(Calc!C13>=Calc!D13,"↑ ","↓ ")&TEXT(ABS(Calc!C13/Calc!D13-1),"0.0%")&" vs "&Calc!$C$7) -> ↑ 9.2% vs 2024 | M6: =IF(OR(NOT(Calc!$C$9),Calc!D14=0),"No earlier data",IF(Calc!C14>=Calc!D14,"↑ ","↓ ")&TEXT(ABS(Calc!C14/Calc!D14-1),"0.0%")&" vs "&Calc!$C$7) -> ↑ 12.2% vs 2024 | Q6: =IF(OR(NOT(Calc!$C$9),Calc!D15=0),"No earlier data",IF(Calc!C15>=Calc!D15,"↑ ","↓ ")&TEXT(ABS(Calc!C15/Calc!D15-1),"0.0%")&" vs "&Calc!$C$7) -> ↑ 1.4% vs 2024
B7: =HYPERLINK("#'Overview'!A1","Overview") -> Overview
B9: =HYPERLINK("#'Sales'!A1","▮▮") -> ▮▮
B10: =HYPERLINK("#'Sales'!A1","Sales") -> Sales
B12: =HYPERLINK("#'Products'!A1","◈") -> ◈
B13: =HYPERLINK("#'Products'!A1","Products") -> Products
B15: =HYPERLINK("#'Customers'!A1","☺") -> ☺
B16: =HYPERLINK("#'Customers'!A1","Customers") -> Customers
B18: =HYPERLINK("#'Orders'!A1","☰") -> ☰
B19: =HYPERLINK("#'Orders'!A1","Orders") -> Orders
D22: TOP 5 PRODUCTS | P22: RECENT ORDERS
D23: Product | F23: Sales | P23: Customer | Q23: Date | R23: Amount
D24: =Calc!J36 -> Smart Watch S2 | E24: =Calc!K36 -> 31683 | F24: =Calc!K36 -> 31683 | P24: =Calc!K44 -> Ryan Wilson | Q24: =Calc!L44 -> 46022 | R24: =Calc!M44 -> 49
D25: =Calc!J37 -> Wireless Earbuds Pro | E25: =Calc!K37 -> 17622 | F25: =Calc!K37 -> 17622 | P25: =Calc!K45 -> Owen Martin | Q25: =Calc!L45 -> 46022 | R25: =Calc!M45 -> 49
D26: =Calc!J38 -> Ceramic Cookware Set | E26: =Calc!K38 -> 13410 | F26: =Calc!K38 -> 13410 | P26: =Calc!K46 -> Chloe Wright | Q26: =Calc!L46 -> 46022 | R26: =Calc!M46 -> 54
D27: =Calc!J39 -> Air Fryer 5L | E27: =Calc!K39 -> 11186 | F27: =Calc!K39 -> 11186 | P27: =Calc!K47 -> Emma King | Q27: =Calc!L47 -> 46022 | R27: =Calc!M47 -> 238
D28: =Calc!J40 -> Bluetooth Speaker | E28: =Calc!K40 -> 11151 | F28: =Calc!K40 -> 11151 | P28: =Calc!K48 -> Liam Clark | Q28: =Calc!L48 -> 46022 | R28: =Calc!M48 -> 178
D33: ="Showing "&Calc!$C$8&" · ↑/↓ compared with "&Calc!$C$7&" · Sales trend and monthly comparison always show the whole year. Crestview Retail Co. is a fictional company (demo data) · Built by Md Muntasir Mamun Mojumder" -> Showing Full year 2025 · ↑/↓ compared with 2024 · Sales trend and monthly comparison always show the whole year. Crestview Retail Co. is a fictional company (demo data) · Built by Md Muntasir Mamun Mojumder
B34: Click to open a page

Sheet Sales
B2: Sales by month | G2: ◀ Back to Overview
B3: ="Year: "&Calc!$C$3&" (change Year on the Overview sheet)" -> Year: 2025 (change Year on the Overview sheet)
B5: Month | C5: Sales ($) | D5: Profit ($) | E5: Margin | F5: Orders | G5: Avg order ($)
B6: =Calc!B20 -> Jan | C6: =Calc!C20 -> 10478 | D6: =Calc!E20 -> 5825 | E6: =IF(C6=0,0,D6/C6) -> 0.5559267 | F6: =Calc!F20 -> 108 | G6: =IF(F6=0,0,C6/F6) -> 97.018519
B7: =Calc!B21 -> Feb | C7: =Calc!C21 -> 7012 | D7: =Calc!E21 -> 4035 | E7: =IF(C7=0,0,D7/C7) -> 0.5754421 | F7: =Calc!F21 -> 79 | G7: =IF(F7=0,0,C7/F7) -> 88.759494
B8: =Calc!B22 -> Mar | C8: =Calc!C22 -> 9908 | D8: =Calc!E22 -> 5666 | E8: =IF(C8=0,0,D8/C8) -> 0.57186112 | F8: =Calc!F22 -> 108 | G8: =IF(F8=0,0,C8/F8) -> 91.740741
B9: =Calc!B23 -> Apr | C9: =Calc!C23 -> 11615 | D9: =Calc!E23 -> 6432 | E9: =IF(C9=0,0,D9/C9) -> 0.55376668 | F9: =Calc!F23 -> 117 | G9: =IF(F9=0,0,C9/F9) -> 99.273504
B10: =Calc!B24 -> May | C10: =Calc!C24 -> 13184 | D10: =Calc!E24 -> 7474 | E10: =IF(C10=0,0,D10/C10) -> 0.56689927 | F10: =Calc!F24 -> 134 | G10: =IF(F10=0,0,C10/F10) -> 98.38806
B11: =Calc!B25 -> Jun | C11: =Calc!C25 -> 10831 | D11: =Calc!E25 -> 5983 | E11: =IF(C11=0,0,D11/C11) -> 0.5523959 | F11: =Calc!F25 -> 113 | G11: =IF(F11=0,0,C11/F11) -> 95.849558
B12: =Calc!B26 -> Jul | C12: =Calc!C26 -> 12807 | D12: =Calc!E26 -> 7079 | E12: =IF(C12=0,0,D12/C12) -> 0.55274459 | F12: =Calc!F26 -> 125 | G12: =IF(F12=0,0,C12/F12) -> 102.456
B13: =Calc!B27 -> Aug | C13: =Calc!C27 -> 12764 | D13: =Calc!E27 -> 6954 | E13: =IF(C13=0,0,D13/C13) -> 0.54481354 | F13: =Calc!F27 -> 126 | G13: =IF(F13=0,0,C13/F13) -> 101.30159
B14: =Calc!B28 -> Sep | C14: =Calc!C28 -> 10019 | D14: =Calc!E28 -> 5731 | E14: =IF(C14=0,0,D14/C14) -> 0.57201317 | F14: =Calc!F28 -> 113 | G14: =IF(F14=0,0,C14/F14) -> 88.663717
B15: =Calc!B29 -> Oct | C15: =Calc!C29 -> 13036 | D15: =Calc!E29 -> 7207 | E15: =IF(C15=0,0,D15/C15) -> 0.55285364 | F15: =Calc!F29 -> 133 | G15: =IF(F15=0,0,C15/F15) -> 98.015038
B16: =Calc!B30 -> Nov | C16: =Calc!C30 -> 16289 | D16: =Calc!E30 -> 9036 | E16: =IF(C16=0,0,D16/C16) -> 0.55473019 | F16: =Calc!F30 -> 167 | G16: =IF(F16=0,0,C16/F16) -> 97.538922
B17: =Calc!B31 -> Dec | C17: =Calc!C31 -> 18392 | D17: =Calc!E31 -> 10238 | E17: =IF(C17=0,0,D17/C17) -> 0.55665507 | F17: =Calc!F31 -> 191 | G17: =IF(F17=0,0,C17/F17) -> 96.293194
B18: Total | C18: =SUM(C6:C17) -> 146335 | D18: =SUM(D6:D17) -> 81660 | E18: =IF(C18=0,0,D18/C18) -> 0.55803465 | F18: =SUM(F6:F17) -> 1514 | G18: =IF(F18=0,0,C18/F18) -> 96.654557

Sheet Products
B2: Products | H2: ◀ Back to Overview
B3: ="Period: "&Calc!$C$8&" (change Year / Month on the Overview sheet)" -> Period: Full year 2025 (change Year / Month on the Overview sheet)
B5: Product | C5: Category | D5: Unit price ($) | E5: Units sold | F5: Sales ($) | G5: Profit ($) | H5: Margin
B6: Wireless Earbuds Pro | C6: Electronics | D6: 89 | E6: =Calc!D36 -> 198 | F6: =Calc!C36 -> 17622 | G6: =Calc!E36 -> 9504 | H6: =IF(F6=0,0,G6/F6) -> 0.53932584
B7: Smart Watch S2 | C7: Electronics | D7: 179 | E7: =Calc!D37 -> 177 | F7: =Calc!C37 -> 31683 | G7: =Calc!E37 -> 15399 | H7: =IF(F7=0,0,G7/F7) -> 0.48603352
B8: Bluetooth Speaker | C8: Electronics | D8: 59 | E8: =Calc!D38 -> 189 | F8: =Calc!C38 -> 11151 | G8: =Calc!E38 -> 6048 | H8: =IF(F8=0,0,G8/F8) -> 0.54237288
B9: 4K Streaming Stick | C9: Electronics | D9: 49 | E9: =Calc!D39 -> 191 | F9: =Calc!C39 -> 9359 | G9: =Calc!E39 -> 5157 | H9: =IF(F9=0,0,G9/F9) -> 0.55102041
B10: Everyday Hoodie | C10: Clothing | D10: 54 | E10: =Calc!D40 -> 114 | F10: =Calc!C40 -> 6156 | G10: =Calc!E40 -> 3990 | H10: =IF(F10=0,0,G10/F10) -> 0.64814815
B11: Slim Fit Chinos | C11: Clothing | D11: 46 | E11: =Calc!D41 -> 129 | F11: =Calc!C41 -> 5934 | G11: =Calc!E41 -> 3870 | H11: =IF(F11=0,0,G11/F11) -> 0.65217391
B12: Running Jacket | C12: Clothing | D12: 79 | E12: =Calc!D42 -> 99 | F12: =Calc!C42 -> 7821 | G12: =Calc!E42 -> 4752 | H12: =IF(F12=0,0,G12/F12) -> 0.60759494
B13: Cotton Tee 3-Pack | C13: Clothing | D13: 29 | E13: =Calc!D43 -> 141 | F13: =Calc!C43 -> 4089 | G13: =Calc!E43 -> 2820 | H13: =IF(F13=0,0,G13/F13) -> 0.68965517
B14: Air Fryer 5L | C14: Home & Kitchen | D14: 119 | E14: =Calc!D44 -> 94 | F14: =Calc!C44 -> 11186 | G14: =Calc!E44 -> 5264 | H14: =IF(F14=0,0,G14/F14) -> 0.47058824
B15: Ceramic Cookware Set | C15: Home & Kitchen | D15: 149 | E15: =Calc!D45 -> 90 | F15: =Calc!C45 -> 13410 | G15: =Calc!E45 -> 7020 | H15: =IF(F15=0,0,G15/F15) -> 0.52348993
B16: Cold Brew Maker | C16: Home & Kitchen | D16: 34 | E16: =Calc!D46 -> 139 | F16: =Calc!C46 -> 4726 | G16: =Calc!E46 -> 3058 | H16: =IF(F16=0,0,G16/F16) -> 0.64705882
B17: Linen Bedding Set | C17: Home & Kitchen | D17: 99 | E17: =Calc!D47 -> 93 | F17: =Calc!C47 -> 9207 | G17: =Calc!E47 -> 5673 | H17: =IF(F17=0,0,G17/F17) -> 0.61616162
... B23: Desk Lamp LED | C23: Others | D23: 42 | E23: =Calc!D53 -> 36 | F23: =Calc!C53 -> 1512 | G23: =Calc!E53 -> 900 | H23: =IF(F23=0,0,G23/F23) -> 0.5952381

Sheet Customers
B2: Top 15 customers | F2: ◀ Back to Overview
B3: ="Period: "&Calc!$C$8&" (change Year / Month on the Overview sheet)" -> Period: Full year 2025 (change Year / Month on the Overview sheet)
B5: Rank | C5: Customer | D5: Region | E5: Orders | F5: Sales ($)
B6: 1 | C6: =INDEX(Calc!$B$61:$B$580,MATCH(1,Calc!$G$61:$G$580,0)) -> Olivia Martin | D6: =INDEX(Calc!$C$61:$C$580,MATCH(1,Calc!$G$61:$G$580,0)) -> North | E6: =INDEX(Calc!$E$61:$E$580,MATCH(1,Calc!$G$61:$G$580,0)) -> 18 | F6: =INDEX(Calc!$D$61:$D$580,MATCH(1,Calc!$G$61:$G$580,0)) -> 2070
B7: 2 | C7: =INDEX(Calc!$B$61:$B$580,MATCH(2,Calc!$G$61:$G$580,0)) -> Sophia Johnson | D7: =INDEX(Calc!$C$61:$C$580,MATCH(2,Calc!$G$61:$G$580,0)) -> South | E7: =INDEX(Calc!$E$61:$E$580,MATCH(2,Calc!$G$61:$G$580,0)) -> 10 | F7: =INDEX(Calc!$D$61:$D$580,MATCH(2,Calc!$G$61:$G$580,0)) -> 1650
B8: 3 | C8: =INDEX(Calc!$B$61:$B$580,MATCH(3,Calc!$G$61:$G$580,0)) -> Mia Wright | D8: =INDEX(Calc!$C$61:$C$580,MATCH(3,Calc!$G$61:$G$580,0)) -> North | E8: =INDEX(Calc!$E$61:$E$580,MATCH(3,Calc!$G$61:$G$580,0)) -> 10 | F8: =INDEX(Calc!$D$61:$D$580,MATCH(3,Calc!$G$61:$G$580,0)) -> 1426
B9: 4 | C9: =INDEX(Calc!$B$61:$B$580,MATCH(4,Calc!$G$61:$G$580,0)) -> Liam Scott | D9: =INDEX(Calc!$C$61:$C$580,MATCH(4,Calc!$G$61:$G$580,0)) -> South | E9: =INDEX(Calc!$E$61:$E$580,MATCH(4,Calc!$G$61:$G$580,0)) -> 10 | F9: =INDEX(Calc!$D$61:$D$580,MATCH(4,Calc!$G$61:$G$580,0)) -> 1372
B10: 5 | C10: =INDEX(Calc!$B$61:$B$580,MATCH(5,Calc!$G$61:$G$580,0)) -> Nora Scott | D10: =INDEX(Calc!$C$61:$C$580,MATCH(5,Calc!$G$61:$G$580,0)) -> East | E10: =INDEX(Calc!$E$61:$E$580,MATCH(5,Calc!$G$61:$G$580,0)) -> 11 | F10: =INDEX(Calc!$D$61:$D$580,MATCH(5,Calc!$G$61:$G$580,0)) -> 1301
B11: 6 | C11: =INDEX(Calc!$B$61:$B$580,MATCH(6,Calc!$G$61:$G$580,0)) -> Harper Moore | D11: =INDEX(Calc!$C$61:$C$580,MATCH(6,Calc!$G$61:$G$580,0)) -> South | E11: =INDEX(Calc!$E$61:$E$580,MATCH(6,Calc!$G$61:$G$580,0)) -> 12 | F11: =INDEX(Calc!$D$61:$D$580,MATCH(6,Calc!$G$61:$G$580,0)) -> 1297
B12: 7 | C12: =INDEX(Calc!$B$61:$B$580,MATCH(7,Calc!$G$61:$G$580,0)) -> Liam Wilson | D12: =INDEX(Calc!$C$61:$C$580,MATCH(7,Calc!$G$61:$G$580,0)) -> South | E12: =INDEX(Calc!$E$61:$E$580,MATCH(7,Calc!$G$61:$G$580,0)) -> 12 | F12: =INDEX(Calc!$D$61:$D$580,MATCH(7,Calc!$G$61:$G$580,0)) -> 1193
B13: 8 | C13: =INDEX(Calc!$B$61:$B$580,MATCH(8,Calc!$G$61:$G$580,0)) -> Harper Thomas | D13: =INDEX(Calc!$C$61:$C$580,MATCH(8,Calc!$G$61:$G$580,0)) -> North | E13: =INDEX(Calc!$E$61:$E$580,MATCH(8,Calc!$G$61:$G$580,0)) -> 10 | F13: =INDEX(Calc!$D$61:$D$580,MATCH(8,Calc!$G$61:$G$580,0)) -> 1169
B14: 9 | C14: =INDEX(Calc!$B$61:$B$580,MATCH(9,Calc!$G$61:$G$580,0)) -> Ruby Davis | D14: =INDEX(Calc!$C$61:$C$580,MATCH(9,Calc!$G$61:$G$580,0)) -> East | E14: =INDEX(Calc!$E$61:$E$580,MATCH(9,Calc!$G$61:$G$580,0)) -> 9 | F14: =INDEX(Calc!$D$61:$D$580,MATCH(9,Calc!$G$61:$G$580,0)) -> 1159
B15: 10 | C15: =INDEX(Calc!$B$61:$B$580,MATCH(10,Calc!$G$61:$G$580,0)) -> Liam Lewis | D15: =INDEX(Calc!$C$61:$C$580,MATCH(10,Calc!$G$61:$G$580,0)) -> South | E15: =INDEX(Calc!$E$61:$E$580,MATCH(10,Calc!$G$61:$G$580,0)) -> 8 | F15: =INDEX(Calc!$D$61:$D$580,MATCH(10,Calc!$G$61:$G$580,0)) -> 1131
B16: 11 | C16: =INDEX(Calc!$B$61:$B$580,MATCH(11,Calc!$G$61:$G$580,0)) -> Mia Clark | D16: =INDEX(Calc!$C$61:$C$580,MATCH(11,Calc!$G$61:$G$580,0)) -> North | E16: =INDEX(Calc!$E$61:$E$580,MATCH(11,Calc!$G$61:$G$580,0)) -> 12 | F16: =INDEX(Calc!$D$61:$D$580,MATCH(11,Calc!$G$61:$G$580,0)) -> 1113
B17: 12 | C17: =INDEX(Calc!$B$61:$B$580,MATCH(12,Calc!$G$61:$G$580,0)) -> Ava Thomas | D17: =INDEX(Calc!$C$61:$C$580,MATCH(12,Calc!$G$61:$G$580,0)) -> Central | E17: =INDEX(Calc!$E$61:$E$580,MATCH(12,Calc!$G$61:$G$580,0)) -> 7 | F17: =INDEX(Calc!$D$61:$D$580,MATCH(12,Calc!$G$61:$G$580,0)) -> 1076
B18: 13 | C18: =INDEX(Calc!$B$61:$B$580,MATCH(13,Calc!$G$61:$G$580,0)) -> Liam Taylor | D18: =INDEX(Calc!$C$61:$C$580,MATCH(13,Calc!$G$61:$G$580,0)) -> West | E18: =INDEX(Calc!$E$61:$E$580,MATCH(13,Calc!$G$61:$G$580,0)) -> 9 | F18: =INDEX(Calc!$D$61:$D$580,MATCH(13,Calc!$G$61:$G$580,0)) -> 1075
B19: 14 | C19: =INDEX(Calc!$B$61:$B$580,MATCH(14,Calc!$G$61:$G$580,0)) -> Caleb Miller | D19: =INDEX(Calc!$C$61:$C$580,MATCH(14,Calc!$G$61:$G$580,0)) -> East | E19: =INDEX(Calc!$E$61:$E$580,MATCH(14,Calc!$G$61:$G$580,0)) -> 8 | F19: =INDEX(Calc!$D$61:$D$580,MATCH(14,Calc!$G$61:$G$580,0)) -> 1068
B20: 15 | C20: =INDEX(Calc!$B$61:$B$580,MATCH(15,Calc!$G$61:$G$580,0)) -> Lucas Taylor | D20: =INDEX(Calc!$C$61:$C$580,MATCH(15,Calc!$G$61:$G$580,0)) -> East | E20: =INDEX(Calc!$E$61:$E$580,MATCH(15,Calc!$G$61:$G$580,0)) -> 8 | F20: =INDEX(Calc!$D$61:$D$580,MATCH(15,Calc!$G$61:$G$580,0)) -> 1007

Sheet Orders
A1: Order ID | B1: Date | C1: Year | D1: Month # | E1: Customer | F1: Region | G1: Category | H1: Product | I1: Qty | J1: Unit price ($) | K1: Unit cost ($) | L1: Sales ($) | M1: Profit ($) | N1: New customer (year) | O1: New customer (month) | P1: In view # | R1: ◀ Back to Overview
A2: CR-10001 | B2: 45292 | C2: =YEAR(B2) -> 2024 | D2: =MONTH(B2) -> 1 | E2: Harper Moore | F2: South | G2: Electronics | H2: 4K Streaming Stick | I2: 3 | J2: 49 | K2: 22 | L2: =I2*J2 -> 147 | M2: =L2-I2*K2 -> 81 | N2: =IF(COUNTIFS(E$2:E2,E2,C$2:C2,C2)=1,1,0) -> 1 | O2: =IF(COUNTIFS(E$2:E2,E2,C$2:C2,C2,D$2:D2,D2)=1,1,0) -> 1 | P2: =IF(AND(C2=Calc!$C$3,OR(Calc!$C$4=0,D2=Calc!$C$4)),ROW(),0) -> 0
A3: CR-10002 | B3: 45292 | C3: =YEAR(B3) -> 2024 | D3: =MONTH(B3) -> 1 | E3: Olivia Brown | F3: West | G3: Electronics | H3: Smart Watch S2 | I3: 1 | J3: 179 | K3: 92 | L3: =I3*J3 -> 179 | M3: =L3-I3*K3 -> 87 | N3: =IF(COUNTIFS(E$2:E3,E3,C$2:C3,C3)=1,1,0) -> 1 | O3: =IF(COUNTIFS(E$2:E3,E3,C$2:C3,C3,D$2:D3,D3)=1,1,0) -> 1 | P3: =IF(AND(C3=Calc!$C$3,OR(Calc!$C$4=0,D3=Calc!$C$4)),ROW(),0) -> 0
A4: CR-10003 | B4: 45293 | C4: =YEAR(B4) -> 2024 | D4: =MONTH(B4) -> 1 | E4: Olivia Wilson | F4: North | G4: Electronics | H4: 4K Streaming Stick | I4: 1 | J4: 49 | K4: 22 | L4: =I4*J4 -> 49 | M4: =L4-I4*K4 -> 27 | N4: =IF(COUNTIFS(E$2:E4,E4,C$2:C4,C4)=1,1,0) -> 1 | O4: =IF(COUNTIFS(E$2:E4,E4,C$2:C4,C4,D$2:D4,D4)=1,1,0) -> 1 | P4: =IF(AND(C4=Calc!$C$3,OR(Calc!$C$4=0,D4=Calc!$C$4)),ROW(),0) -> 0
A5: CR-10004 | B5: 45293 | C5: =YEAR(B5) -> 2024 | D5: =MONTH(B5) -> 1 | E5: Harper Lewis | F5: East | G5: Clothing | H5: Slim Fit Chinos | I5: 1 | J5: 46 | K5: 16 | L5: =I5*J5 -> 46 | M5: =L5-I5*K5 -> 30 | N5: =IF(COUNTIFS(E$2:E5,E5,C$2:C5,C5)=1,1,0) -> 1 | O5: =IF(COUNTIFS(E$2:E5,E5,C$2:C5,C5,D$2:D5,D5)=1,1,0) -> 1 | P5: =IF(AND(C5=Calc!$C$3,OR(Calc!$C$4=0,D5=Calc!$C$4)),ROW(),0) -> 0
A6: CR-10005 | B6: 45294 | C6: =YEAR(B6) -> 2024 | D6: =MONTH(B6) -> 1 | E6: Mia Taylor | F6: Central | G6: Others | H6: Yoga Mat | I6: 3 | J6: 39 | K6: 13 | L6: =I6*J6 -> 117 | M6: =L6-I6*K6 -> 78 | N6: =IF(COUNTIFS(E$2:E6,E6,C$2:C6,C6)=1,1,0) -> 1 | O6: =IF(COUNTIFS(E$2:E6,E6,C$2:C6,C6,D$2:D6,D6)=1,1,0) -> 1 | P6: =IF(AND(C6=Calc!$C$3,OR(Calc!$C$4=0,D6=Calc!$C$4)),ROW(),0) -> 0
A7: CR-10006 | B7: 45294 | C7: =YEAR(B7) -> 2024 | D7: =MONTH(B7) -> 1 | E7: Lucas Wilson | F7: North | G7: Clothing | H7: Cotton Tee 3-Pack | I7: 1 | J7: 29 | K7: 9 | L7: =I7*J7 -> 29 | M7: =L7-I7*K7 -> 20 | N7: =IF(COUNTIFS(E$2:E7,E7,C$2:C7,C7)=1,1,0) -> 1 | O7: =IF(COUNTIFS(E$2:E7,E7,C$2:C7,C7,D$2:D7,D7)=1,1,0) -> 1 | P7: =IF(AND(C7=Calc!$C$3,OR(Calc!$C$4=0,D7=Calc!$C$4)),ROW(),0) -> 0
A8: CR-10007 | B8: 45294 | C8: =YEAR(B8) -> 2024 | D8: =MONTH(B8) -> 1 | E8: Jack Davis | F8: South | G8: Electronics | H8: 4K Streaming Stick | I8: 1 | J8: 49 | K8: 22 | L8: =I8*J8 -> 49 | M8: =L8-I8*K8 -> 27 | N8: =IF(COUNTIFS(E$2:E8,E8,C$2:C8,C8)=1,1,0) -> 1 | O8: =IF(COUNTIFS(E$2:E8,E8,C$2:C8,C8,D$2:D8,D8)=1,1,0) -> 1 | P8: =IF(AND(C8=Calc!$C$3,OR(Calc!$C$4=0,D8=Calc!$C$4)),ROW(),0) -> 0
A9: CR-10008 | B9: 45294 | C9: =YEAR(B9) -> 2024 | D9: =MONTH(B9) -> 1 | E9: Ryan Miller | F9: West | G9: Home & Kitchen | H9: Air Fryer 5L | I9: 3 | J9: 119 | K9: 63 | L9: =I9*J9 -> 357 | M9: =L9-I9*K9 -> 168 | N9: =IF(COUNTIFS(E$2:E9,E9,C$2:C9,C9)=1,1,0) -> 1 | O9: =IF(COUNTIFS(E$2:E9,E9,C$2:C9,C9,D$2:D9,D9)=1,1,0) -> 1 | P9: =IF(AND(C9=Calc!$C$3,OR(Calc!$C$4=0,D9=Calc!$C$4)),ROW(),0) -> 0
A10: CR-10009 | B10: 45295 | C10: =YEAR(B10) -> 2024 | D10: =MONTH(B10) -> 1 | E10: Harper King | F10: Central | G10: Electronics | H10: Smart Watch S2 | I10: 3 | J10: 179 | K10: 92 | L10: =I10*J10 -> 537 | M10: =L10-I10*K10 -> 261 | N10: =IF(COUNTIFS(E$2:E10,E10,C$2:C10,C10)=1,1,0) -> 1 | O10: =IF(COUNTIFS(E$2:E10,E10,C$2:C10,C10,D$2:D10,D10)=1,1,0) -> 1 | P10: =IF(AND(C10=Calc!$C$3,OR(Calc!$C$4=0,D10=Calc!$C$4)),ROW(),0) -> 0
A11: CR-10010 | B11: 45296 | C11: =YEAR(B11) -> 2024 | D11: =MONTH(B11) -> 1 | E11: Ethan King | F11: South | G11: Electronics | H11: 4K Streaming Stick | I11: 3 | J11: 49 | K11: 22 | L11: =I11*J11 -> 147 | M11: =L11-I11*K11 -> 81 | N11: =IF(COUNTIFS(E$2:E11,E11,C$2:C11,C11)=1,1,0) -> 1 | O11: =IF(COUNTIFS(E$2:E11,E11,C$2:C11,C11,D$2:D11,D11)=1,1,0) -> 1 | P11: =IF(AND(C11=Calc!$C$3,OR(Calc!$C$4=0,D11=Calc!$C$4)),ROW(),0) -> 0
A12: CR-10011 | B12: 45296 | C12: =YEAR(B12) -> 2024 | D12: =MONTH(B12) -> 1 | E12: Ava Wilson | F12: Central | G12: Clothing | H12: Everyday Hoodie | I12: 1 | J12: 54 | K12: 19 | L12: =I12*J12 -> 54 | M12: =L12-I12*K12 -> 35 | N12: =IF(COUNTIFS(E$2:E12,E12,C$2:C12,C12)=1,1,0) -> 1 | O12: =IF(COUNTIFS(E$2:E12,E12,C$2:C12,C12,D$2:D12,D12)=1,1,0) -> 1 | P12: =IF(AND(C12=Calc!$C$3,OR(Calc!$C$4=0,D12=Calc!$C$4)),ROW(),0) -> 0
A13: CR-10012 | B13: 45297 | C13: =YEAR(B13) -> 2024 | D13: =MONTH(B13) -> 1 | E13: Grace Anderson | F13: North | G13: Clothing | H13: Cotton Tee 3-Pack | I13: 1 | J13: 29 | K13: 9 | L13: =I13*J13 -> 29 | M13: =L13-I13*K13 -> 20 | N13: =IF(COUNTIFS(E$2:E13,E13,C$2:C13,C13)=1,1,0) -> 1 | O13: =IF(COUNTIFS(E$2:E13,E13,C$2:C13,C13,D$2:D13,D13)=1,1,0) -> 1 | P13: =IF(AND(C13=Calc!$C$3,OR(Calc!$C$4=0,D13=Calc!$C$4)),ROW(),0) -> 0
... A2864: CR-12863 | B2864: 46022 | C2864: =YEAR(B2864) -> 2025 | D2864: =MONTH(B2864) -> 12 | E2864: Ryan Wilson | F2864: North | G2864: Electronics | H2864: 4K Streaming Stick | I2864: 1 | J2864: 49 | K2864: 22 | L2864: =I2864*J2864 -> 49 | M2864: =L2864-I2864*K2864 -> 27 | N2864: =IF(COUNTIFS(E$2:E2864,E2864,C$2:C2864,C2864)=1,1,0) -> 0 | O2864: =IF(COUNTIFS(E$2:E2864,E2864,C$2:C2864,C2864,D$2:D2864,D2864)=1,1,0) -> 1 | P2864: =IF(AND(C2864=Calc!$C$3,OR(Calc!$C$4=0,D2864=Calc!$C$4)),ROW(),0) -> 2864

Sheet Calc
A1: Helper calculations (do not edit). Filters come from the Overview sheet.
B3: Year | C3: =Overview!$N$2 -> 2025
B4: Month # (0 = all) | C4: =IF(Overview!$Q$2="All",0,MATCH(Overview!$Q$2,Lists!$B$3:$B$14,0)) -> 0
B5: Previous year | C5: =IF($C$4=0,$C$3-1,IF($C$4=1,$C$3-1,$C$3)) -> 2024
B6: Previous month # (0 = all) | C6: =IF($C$4=0,0,IF($C$4=1,12,$C$4-1)) -> 0
B7: Previous period label | C7: =IF($C$4=0,$C$5,INDEX(Lists!$B$3:$B$14,$C$6)&" "&$C$5) -> 2024
B8: Period label | C8: =IF($C$4=0,"Full year "&$C$3,INDEX(Lists!$B$3:$B$14,$C$4)&" "&$C$3) -> Full year 2025
B9: Earlier data exists? | C9: =COUNTIF(Orders!$C$2:$C$2864,$C$5)>0 -> TRUE
B11: KPI | C11: Selected period | D11: Previous period
B12: Total sales | C12: =SUMIFS(Orders!$L$2:$L$2864,Orders!$C$2:$C$2864,$C$3,Orders!$D$2:$D$2864,IF($C$4=0,">0",$C$4)) -> 146335 | D12: =SUMIFS(Orders!$L$2:$L$2864,Orders!$C$2:$C$2864,$C$5,Orders!$D$2:$D$2864,IF($C$6=0,">0",$C$6)) -> 134595
B13: Total profit | C13: =SUMIFS(Orders!$M$2:$M$2864,Orders!$C$2:$C$2864,$C$3,Orders!$D$2:$D$2864,IF($C$4=0,">0",$C$4)) -> 81660 | D13: =SUMIFS(Orders!$M$2:$M$2864,Orders!$C$2:$C$2864,$C$5,Orders!$D$2:$D$2864,IF($C$6=0,">0",$C$6)) -> 74774
B14: Total orders | C14: =COUNTIFS(Orders!$C$2:$C$2864,$C$3,Orders!$D$2:$D$2864,IF($C$4=0,">0",$C$4)) -> 1514 | D14: =COUNTIFS(Orders!$C$2:$C$2864,$C$5,Orders!$D$2:$D$2864,IF($C$6=0,">0",$C$6)) -> 1349
B15: Total customers | C15: =IF($C$4=0,SUMIFS(Orders!$N$2:$N$2864,Orders!$C$2:$C$2864,$C$3),SUMIFS(Orders!$O$2:$O$2864,Orders!$C$2:$C$2864,$C$3,Orders!$D$2:$D$2864,$C$4)) -> 448 | D15: =IF($C$6=0,SUMIFS(Orders!$N$2:$N$2864,Orders!$C$2:$C$2864,$C$5),SUMIFS(Orders!$O$2:$O$2864,Orders!$C$2:$C$2864,$C$5,Orders!$D$2:$D$2864,$C$6)) -> 442
B16: Profit margin | C16: =IF(C12=0,0,C13/C12) -> 0.55803465 | D16: =IF(D12=0,0,D13/D12) -> 0.55554813
B19: Month | C19: =$C$3 -> 2025 | D19: =$C$3-1 -> 2024 | E19: Profit | F19: Orders | H19: Category | I19: Sales | K19: Region | L19: Sales
B20: Jan | C20: =SUMIFS(Orders!$L$2:$L$2864,Orders!$C$2:$C$2864,$C$3,Orders!$D$2:$D$2864,1) -> 10478 | D20: =SUMIFS(Orders!$L$2:$L$2864,Orders!$C$2:$C$2864,$C$3-1,Orders!$D$2:$D$2864,1) -> 8752 | E20: =SUMIFS(Orders!$M$2:$M$2864,Orders!$C$2:$C$2864,$C$3,Orders!$D$2:$D$2864,1) -> 5825 | F20: =COUNTIFS(Orders!$C$2:$C$2864,$C$3,Orders!$D$2:$D$2864,1) -> 108 | H20: Electronics | I20: =SUMIFS(Orders!$L$2:$L$2864,Orders!$C$2:$C$2864,$C$3,Orders!$D$2:$D$2864,IF($C$4=0,">0",$C$4),Orders!$G$2:$G$2864,H20) -> 69815 | K20: North | L20: =SUMIFS(Orders!$L$2:$L$2864,Orders!$C$2:$C$2864,$C$3,Orders!$D$2:$D$2864,IF($C$4=0,">0",$C$4),Orders!$F$2:$F$2864,K20) -> 35816
B21: Feb | C21: =SUMIFS(Orders!$L$2:$L$2864,Orders!$C$2:$C$2864,$C$3,Orders!$D$2:$D$2864,2) -> 7012 | D21: =SUMIFS(Orders!$L$2:$L$2864,Orders!$C$2:$C$2864,$C$3-1,Orders!$D$2:$D$2864,2) -> 6282 | E21: =SUMIFS(Orders!$M$2:$M$2864,Orders!$C$2:$C$2864,$C$3,Orders!$D$2:$D$2864,2) -> 4035 | F21: =COUNTIFS(Orders!$C$2:$C$2864,$C$3,Orders!$D$2:$D$2864,2) -> 79 | H21: Clothing | I21: =SUMIFS(Orders!$L$2:$L$2864,Orders!$C$2:$C$2864,$C$3,Orders!$D$2:$D$2864,IF($C$4=0,">0",$C$4),Orders!$G$2:$G$2864,H21) -> 24000 | K21: South | L21: =SUMIFS(Orders!$L$2:$L$2864,Orders!$C$2:$C$2864,$C$3,Orders!$D$2:$D$2864,IF($C$4=0,">0",$C$4),Orders!$F$2:$F$2864,K21) -> 36753
B22: Mar | C22: =SUMIFS(Orders!$L$2:$L$2864,Orders!$C$2:$C$2864,$C$3,Orders!$D$2:$D$2864,3) -> 9908 | D22: =SUMIFS(Orders!$L$2:$L$2864,Orders!$C$2:$C$2864,$C$3-1,Orders!$D$2:$D$2864,3) -> 9882 | E22: =SUMIFS(Orders!$M$2:$M$2864,Orders!$C$2:$C$2864,$C$3,Orders!$D$2:$D$2864,3) -> 5666 | F22: =COUNTIFS(Orders!$C$2:$C$2864,$C$3,Orders!$D$2:$D$2864,3) -> 108 | H22: Home & Kitchen | I22: =SUMIFS(Orders!$L$2:$L$2864,Orders!$C$2:$C$2864,$C$3,Orders!$D$2:$D$2864,IF($C$4=0,">0",$C$4),Orders!$G$2:$G$2864,H22) -> 38529 | K22: East | L22: =SUMIFS(Orders!$L$2:$L$2864,Orders!$C$2:$C$2864,$C$3,Orders!$D$2:$D$2864,IF($C$4=0,">0",$C$4),Orders!$F$2:$F$2864,K22) -> 36149
B23: Apr | C23: =SUMIFS(Orders!$L$2:$L$2864,Orders!$C$2:$C$2864,$C$3,Orders!$D$2:$D$2864,4) -> 11615 | D23: =SUMIFS(Orders!$L$2:$L$2864,Orders!$C$2:$C$2864,$C$3-1,Orders!$D$2:$D$2864,4) -> 9934 | E23: =SUMIFS(Orders!$M$2:$M$2864,Orders!$C$2:$C$2864,$C$3,Orders!$D$2:$D$2864,4) -> 6432 | F23: =COUNTIFS(Orders!$C$2:$C$2864,$C$3,Orders!$D$2:$D$2864,4) -> 117 | H23: Beauty | I23: =SUMIFS(Orders!$L$2:$L$2864,Orders!$C$2:$C$2864,$C$3,Orders!$D$2:$D$2864,IF($C$4=0,">0",$C$4),Orders!$G$2:$G$2864,H23) -> 9542 | K23: West | L23: =SUMIFS(Orders!$L$2:$L$2864,Orders!$C$2:$C$2864,$C$3,Orders!$D$2:$D$2864,IF($C$4=0,">0",$C$4),Orders!$F$2:$F$2864,K23) -> 18737
B24: May | C24: =SUMIFS(Orders!$L$2:$L$2864,Orders!$C$2:$C$2864,$C$3,Orders!$D$2:$D$2864,5) -> 13184 | D24: =SUMIFS(Orders!$L$2:$L$2864,Orders!$C$2:$C$2864,$C$3-1,Orders!$D$2:$D$2864,5) -> 12553 | E24: =SUMIFS(Orders!$M$2:$M$2864,Orders!$C$2:$C$2864,$C$3,Orders!$D$2:$D$2864,5) -> 7474 | F24: =COUNTIFS(Orders!$C$2:$C$2864,$C$3,Orders!$D$2:$D$2864,5) -> 134 | H24: Others | I24: =SUMIFS(Orders!$L$2:$L$2864,Orders!$C$2:$C$2864,$C$3,Orders!$D$2:$D$2864,IF($C$4=0,">0",$C$4),Orders!$G$2:$G$2864,H24) -> 4449 | K24: Central | L24: =SUMIFS(Orders!$L$2:$L$2864,Orders!$C$2:$C$2864,$C$3,Orders!$D$2:$D$2864,IF($C$4=0,">0",$C$4),Orders!$F$2:$F$2864,K24) -> 18880
B25: Jun | C25: =SUMIFS(Orders!$L$2:$L$2864,Orders!$C$2:$C$2864,$C$3,Orders!$D$2:$D$2864,6) -> 10831 | D25: =SUMIFS(Orders!$L$2:$L$2864,Orders!$C$2:$C$2864,$C$3-1,Orders!$D$2:$D$2864,6) -> 9668 | E25: =SUMIFS(Orders!$M$2:$M$2864,Orders!$C$2:$C$2864,$C$3,Orders!$D$2:$D$2864,6) -> 5983 | F25: =COUNTIFS(Orders!$C$2:$C$2864,$C$3,Orders!$D$2:$D$2864,6) -> 113
B26: Jul | C26: =SUMIFS(Orders!$L$2:$L$2864,Orders!$C$2:$C$2864,$C$3,Orders!$D$2:$D$2864,7) -> 12807 | D26: =SUMIFS(Orders!$L$2:$L$2864,Orders!$C$2:$C$2864,$C$3-1,Orders!$D$2:$D$2864,7) -> 10537 | E26: =SUMIFS(Orders!$M$2:$M$2864,Orders!$C$2:$C$2864,$C$3,Orders!$D$2:$D$2864,7) -> 7079 | F26: =COUNTIFS(Orders!$C$2:$C$2864,$C$3,Orders!$D$2:$D$2864,7) -> 125
B27: Aug | C27: =SUMIFS(Orders!$L$2:$L$2864,Orders!$C$2:$C$2864,$C$3,Orders!$D$2:$D$2864,8) -> 12764 | D27: =SUMIFS(Orders!$L$2:$L$2864,Orders!$C$2:$C$2864,$C$3-1,Orders!$D$2:$D$2864,8) -> 10954 | E27: =SUMIFS(Orders!$M$2:$M$2864,Orders!$C$2:$C$2864,$C$3,Orders!$D$2:$D$2864,8) -> 6954 | F27: =COUNTIFS(Orders!$C$2:$C$2864,$C$3,Orders!$D$2:$D$2864,8) -> 126
B28: Sep | C28: =SUMIFS(Orders!$L$2:$L$2864,Orders!$C$2:$C$2864,$C$3,Orders!$D$2:$D$2864,9) -> 10019 | D28: =SUMIFS(Orders!$L$2:$L$2864,Orders!$C$2:$C$2864,$C$3-1,Orders!$D$2:$D$2864,9) -> 10759 | E28: =SUMIFS(Orders!$M$2:$M$2864,Orders!$C$2:$C$2864,$C$3,Orders!$D$2:$D$2864,9) -> 5731 | F28: =COUNTIFS(Orders!$C$2:$C$2864,$C$3,Orders!$D$2:$D$2864,9) -> 113
B29: Oct | C29: =SUMIFS(Orders!$L$2:$L$2864,Orders!$C$2:$C$2864,$C$3,Orders!$D$2:$D$2864,10) -> 13036 | D29: =SUMIFS(Orders!$L$2:$L$2864,Orders!$C$2:$C$2864,$C$3-1,Orders!$D$2:$D$2864,10) -> 11894 | E29: =SUMIFS(Orders!$M$2:$M$2864,Orders!$C$2:$C$2864,$C$3,Orders!$D$2:$D$2864,10) -> 7207 | F29: =COUNTIFS(Orders!$C$2:$C$2864,$C$3,Orders!$D$2:$D$2864,10) -> 133
B30: Nov | C30: =SUMIFS(Orders!$L$2:$L$2864,Orders!$C$2:$C$2864,$C$3,Orders!$D$2:$D$2864,11) -> 16289 | D30: =SUMIFS(Orders!$L$2:$L$2864,Orders!$C$2:$C$2864,$C$3-1,Orders!$D$2:$D$2864,11) -> 13765 | E30: =SUMIFS(Orders!$M$2:$M$2864,Orders!$C$2:$C$2864,$C$3,Orders!$D$2:$D$2864,11) -> 9036 | F30: =COUNTIFS(Orders!$C$2:$C$2864,$C$3,Orders!$D$2:$D$2864,11) -> 167
B31: Dec | C31: =SUMIFS(Orders!$L$2:$L$2864,Orders!$C$2:$C$2864,$C$3,Orders!$D$2:$D$2864,12) -> 18392 | D31: =SUMIFS(Orders!$L$2:$L$2864,Orders!$C$2:$C$2864,$C$3-1,Orders!$D$2:$D$2864,12) -> 19615 | E31: =SUMIFS(Orders!$M$2:$M$2864,Orders!$C$2:$C$2864,$C$3,Orders!$D$2:$D$2864,12) -> 10238 | F31: =COUNTIFS(Orders!$C$2:$C$2864,$C$3,Orders!$D$2:$D$2864,12) -> 191
B35: Product | C35: Sales | D35: Units | E35: Profit | F35: Sort key | G35: Rank | I35: Top # | J35: Product | K35: Sales
B36: Wireless Earbuds Pro | C36: =SUMIFS(Orders!$L$2:$L$2864,Orders!$C$2:$C$2864,$C$3,Orders!$D$2:$D$2864,IF($C$4=0,">0",$C$4),Orders!$H$2:$H$2864,B36) -> 17622 | D36: =SUMIFS(Orders!$I$2:$I$2864,Orders!$C$2:$C$2864,$C$3,Orders!$D$2:$D$2864,IF($C$4=0,">0",$C$4),Orders!$H$2:$H$2864,B36) -> 198 | E36: =SUMIFS(Orders!$M$2:$M$2864,Orders!$C$2:$C$2864,$C$3,Orders!$D$2:$D$2864,IF($C$4=0,">0",$C$4),Orders!$H$2:$H$2864,B36) -> 9504 | F36: =C36+ROW()/1000 -> 17622.036 | G36: =RANK(F36,$F$36:$F$53) -> 2 | I36: 1 | J36: =INDEX($B$36:$B$53,MATCH(I36,$G$36:$G$53,0)) -> Smart Watch S2 | K36: =INDEX($C$36:$C$53,MATCH(I36,$G$36:$G$53,0)) -> 31683
B37: Smart Watch S2 | C37: =SUMIFS(Orders!$L$2:$L$2864,Orders!$C$2:$C$2864,$C$3,Orders!$D$2:$D$2864,IF($C$4=0,">0",$C$4),Orders!$H$2:$H$2864,B37) -> 31683 | D37: =SUMIFS(Orders!$I$2:$I$2864,Orders!$C$2:$C$2864,$C$3,Orders!$D$2:$D$2864,IF($C$4=0,">0",$C$4),Orders!$H$2:$H$2864,B37) -> 177 | E37: =SUMIFS(Orders!$M$2:$M$2864,Orders!$C$2:$C$2864,$C$3,Orders!$D$2:$D$2864,IF($C$4=0,">0",$C$4),Orders!$H$2:$H$2864,B37) -> 15399 | F37: =C37+ROW()/1000 -> 31683.037 | G37: =RANK(F37,$F$36:$F$53) -> 1 | I37: 2 | J37: =INDEX($B$36:$B$53,MATCH(I37,$G$36:$G$53,0)) -> Wireless Earbuds Pro | K37: =INDEX($C$36:$C$53,MATCH(I37,$G$36:$G$53,0)) -> 17622
B38: Bluetooth Speaker | C38: =SUMIFS(Orders!$L$2:$L$2864,Orders!$C$2:$C$2864,$C$3,Orders!$D$2:$D$2864,IF($C$4=0,">0",$C$4),Orders!$H$2:$H$2864,B38) -> 11151 | D38: =SUMIFS(Orders!$I$2:$I$2864,Orders!$C$2:$C$2864,$C$3,Orders!$D$2:$D$2864,IF($C$4=0,">0",$C$4),Orders!$H$2:$H$2864,B38) -> 189 | E38: =SUMIFS(Orders!$M$2:$M$2864,Orders!$C$2:$C$2864,$C$3,Orders!$D$2:$D$2864,IF($C$4=0,">0",$C$4),Orders!$H$2:$H$2864,B38) -> 6048 | F38: =C38+ROW()/1000 -> 11151.038 | G38: =RANK(F38,$F$36:$F$53) -> 5 | I38: 3 | J38: =INDEX($B$36:$B$53,MATCH(I38,$G$36:$G$53,0)) -> Ceramic Cookware Set | K38: =INDEX($C$36:$C$53,MATCH(I38,$G$36:$G$53,0)) -> 13410
B39: 4K Streaming Stick | C39: =SUMIFS(Orders!$L$2:$L$2864,Orders!$C$2:$C$2864,$C$3,Orders!$D$2:$D$2864,IF($C$4=0,">0",$C$4),Orders!$H$2:$H$2864,B39) -> 9359 | D39: =SUMIFS(Orders!$I$2:$I$2864,Orders!$C$2:$C$2864,$C$3,Orders!$D$2:$D$2864,IF($C$4=0,">0",$C$4),Orders!$H$2:$H$2864,B39) -> 191 | E39: =SUMIFS(Orders!$M$2:$M$2864,Orders!$C$2:$C$2864,$C$3,Orders!$D$2:$D$2864,IF($C$4=0,">0",$C$4),Orders!$H$2:$H$2864,B39) -> 5157 | F39: =C39+ROW()/1000 -> 9359.039 | G39: =RANK(F39,$F$36:$F$53) -> 6 | I39: 4 | J39: =INDEX($B$36:$B$53,MATCH(I39,$G$36:$G$53,0)) -> Air Fryer 5L | K39: =INDEX($C$36:$C$53,MATCH(I39,$G$36:$G$53,0)) -> 11186
B40: Everyday Hoodie | C40: =SUMIFS(Orders!$L$2:$L$2864,Orders!$C$2:$C$2864,$C$3,Orders!$D$2:$D$2864,IF($C$4=0,">0",$C$4),Orders!$H$2:$H$2864,B40) -> 6156 | D40: =SUMIFS(Orders!$I$2:$I$2864,Orders!$C$2:$C$2864,$C$3,Orders!$D$2:$D$2864,IF($C$4=0,">0",$C$4),Orders!$H$2:$H$2864,B40) -> 114 | E40: =SUMIFS(Orders!$M$2:$M$2864,Orders!$C$2:$C$2864,$C$3,Orders!$D$2:$D$2864,IF($C$4=0,">0",$C$4),Orders!$H$2:$H$2864,B40) -> 3990 | F40: =C40+ROW()/1000 -> 6156.04 | G40: =RANK(F40,$F$36:$F$53) -> 9 | I40: 5 | J40: =INDEX($B$36:$B$53,MATCH(I40,$G$36:$G$53,0)) -> Bluetooth Speaker | K40: =INDEX($C$36:$C$53,MATCH(I40,$G$36:$G$53,0)) -> 11151
B41: Slim Fit Chinos | C41: =SUMIFS(Orders!$L$2:$L$2864,Orders!$C$2:$C$2864,$C$3,Orders!$D$2:$D$2864,IF($C$4=0,">0",$C$4),Orders!$H$2:$H$2864,B41) -> 5934 | D41: =SUMIFS(Orders!$I$2:$I$2864,Orders!$C$2:$C$2864,$C$3,Orders!$D$2:$D$2864,IF($C$4=0,">0",$C$4),Orders!$H$2:$H$2864,B41) -> 129 | E41: =SUMIFS(Orders!$M$2:$M$2864,Orders!$C$2:$C$2864,$C$3,Orders!$D$2:$D$2864,IF($C$4=0,">0",$C$4),Orders!$H$2:$H$2864,B41) -> 3870 | F41: =C41+ROW()/1000 -> 5934.041 | G41: =RANK(F41,$F$36:$F$53) -> 10
B42: Running Jacket | C42: =SUMIFS(Orders!$L$2:$L$2864,Orders!$C$2:$C$2864,$C$3,Orders!$D$2:$D$2864,IF($C$4=0,">0",$C$4),Orders!$H$2:$H$2864,B42) -> 7821 | D42: =SUMIFS(Orders!$I$2:$I$2864,Orders!$C$2:$C$2864,$C$3,Orders!$D$2:$D$2864,IF($C$4=0,">0",$C$4),Orders!$H$2:$H$2864,B42) -> 99 | E42: =SUMIFS(Orders!$M$2:$M$2864,Orders!$C$2:$C$2864,$C$3,Orders!$D$2:$D$2864,IF($C$4=0,">0",$C$4),Orders!$H$2:$H$2864,B42) -> 4752 | F42: =C42+ROW()/1000 -> 7821.042 | G42: =RANK(F42,$F$36:$F$53) -> 8
B43: Cotton Tee 3-Pack | C43: =SUMIFS(Orders!$L$2:$L$2864,Orders!$C$2:$C$2864,$C$3,Orders!$D$2:$D$2864,IF($C$4=0,">0",$C$4),Orders!$H$2:$H$2864,B43) -> 4089 | D43: =SUMIFS(Orders!$I$2:$I$2864,Orders!$C$2:$C$2864,$C$3,Orders!$D$2:$D$2864,IF($C$4=0,">0",$C$4),Orders!$H$2:$H$2864,B43) -> 141 | E43: =SUMIFS(Orders!$M$2:$M$2864,Orders!$C$2:$C$2864,$C$3,Orders!$D$2:$D$2864,IF($C$4=0,">0",$C$4),Orders!$H$2:$H$2864,B43) -> 2820 | F43: =C43+ROW()/1000 -> 4089.043 | G43: =RANK(F43,$F$36:$F$53) -> 13 | I43: Recent # | J43: Row | K43: Customer | L43: Date | M43: Amount
B44: Air Fryer 5L | C44: =SUMIFS(Orders!$L$2:$L$2864,Orders!$C$2:$C$2864,$C$3,Orders!$D$2:$D$2864,IF($C$4=0,">0",$C$4),Orders!$H$2:$H$2864,B44) -> 11186 | D44: =SUMIFS(Orders!$I$2:$I$2864,Orders!$C$2:$C$2864,$C$3,Orders!$D$2:$D$2864,IF($C$4=0,">0",$C$4),Orders!$H$2:$H$2864,B44) -> 94 | E44: =SUMIFS(Orders!$M$2:$M$2864,Orders!$C$2:$C$2864,$C$3,Orders!$D$2:$D$2864,IF($C$4=0,">0",$C$4),Orders!$H$2:$H$2864,B44) -> 5264 | F44: =C44+ROW()/1000 -> 11186.044 | G44: =RANK(F44,$F$36:$F$53) -> 4 | I44: 1 | J44: =LARGE(Orders!$P$2:$P$2864,I44) -> 2864 | K44: =IF(J44=0,"",INDEX(Orders!$E:$E,J44)) -> Ryan Wilson | L44: =IF(J44=0,"",INDEX(Orders!$B:$B,J44)) -> 46022 | M44: =IF(J44=0,"",INDEX(Orders!$L:$L,J44)) -> 49
B45: Ceramic Cookware Set | C45: =SUMIFS(Orders!$L$2:$L$2864,Orders!$C$2:$C$2864,$C$3,Orders!$D$2:$D$2864,IF($C$4=0,">0",$C$4),Orders!$H$2:$H$2864,B45) -> 13410 | D45: =SUMIFS(Orders!$I$2:$I$2864,Orders!$C$2:$C$2864,$C$3,Orders!$D$2:$D$2864,IF($C$4=0,">0",$C$4),Orders!$H$2:$H$2864,B45) -> 90 | E45: =SUMIFS(Orders!$M$2:$M$2864,Orders!$C$2:$C$2864,$C$3,Orders!$D$2:$D$2864,IF($C$4=0,">0",$C$4),Orders!$H$2:$H$2864,B45) -> 7020 | F45: =C45+ROW()/1000 -> 13410.045 | G45: =RANK(F45,$F$36:$F$53) -> 3 | I45: 2 | J45: =LARGE(Orders!$P$2:$P$2864,I45) -> 2863 | K45: =IF(J45=0,"",INDEX(Orders!$E:$E,J45)) -> Owen Martin | L45: =IF(J45=0,"",INDEX(Orders!$B:$B,J45)) -> 46022 | M45: =IF(J45=0,"",INDEX(Orders!$L:$L,J45)) -> 49
B46: Cold Brew Maker | C46: =SUMIFS(Orders!$L$2:$L$2864,Orders!$C$2:$C$2864,$C$3,Orders!$D$2:$D$2864,IF($C$4=0,">0",$C$4),Orders!$H$2:$H$2864,B46) -> 4726 | D46: =SUMIFS(Orders!$I$2:$I$2864,Orders!$C$2:$C$2864,$C$3,Orders!$D$2:$D$2864,IF($C$4=0,">0",$C$4),Orders!$H$2:$H$2864,B46) -> 139 | E46: =SUMIFS(Orders!$M$2:$M$2864,Orders!$C$2:$C$2864,$C$3,Orders!$D$2:$D$2864,IF($C$4=0,">0",$C$4),Orders!$H$2:$H$2864,B46) -> 3058 | F46: =C46+ROW()/1000 -> 4726.046 | G46: =RANK(F46,$F$36:$F$53) -> 11 | I46: 3 | J46: =LARGE(Orders!$P$2:$P$2864,I46) -> 2862 | K46: =IF(J46=0,"",INDEX(Orders!$E:$E,J46)) -> Chloe Wright | L46: =IF(J46=0,"",INDEX(Orders!$B:$B,J46)) -> 46022 | M46: =IF(J46=0,"",INDEX(Orders!$L:$L,J46)) -> 54
B47: Linen Bedding Set | C47: =SUMIFS(Orders!$L$2:$L$2864,Orders!$C$2:$C$2864,$C$3,Orders!$D$2:$D$2864,IF($C$4=0,">0",$C$4),Orders!$H$2:$H$2864,B47) -> 9207 | D47: =SUMIFS(Orders!$I$2:$I$2864,Orders!$C$2:$C$2864,$C$3,Orders!$D$2:$D$2864,IF($C$4=0,">0",$C$4),Orders!$H$2:$H$2864,B47) -> 93 | E47: =SUMIFS(Orders!$M$2:$M$2864,Orders!$C$2:$C$2864,$C$3,Orders!$D$2:$D$2864,IF($C$4=0,">0",$C$4),Orders!$H$2:$H$2864,B47) -> 5673 | F47: =C47+ROW()/1000 -> 9207.047 | G47: =RANK(F47,$F$36:$F$53) -> 7 | I47: 4 | J47: =LARGE(Orders!$P$2:$P$2864,I47) -> 2861 | K47: =IF(J47=0,"",INDEX(Orders!$E:$E,J47)) -> Emma King | L47: =IF(J47=0,"",INDEX(Orders!$B:$B,J47)) -> 46022 | M47: =IF(J47=0,"",INDEX(Orders!$L:$L,J47)) -> 238
...

Sheet Lists
A1: Year | B1: Month
A2: 2025 | B2: All
A3: 2024 | B3: Jan
B4: Feb
B5: Mar
B6: Apr
B7: May
B8: Jun
B9: Jul
B10: Aug
B11: Sep
B12: Oct
B13: Nov
B14: Dec

Sheet How to use
B2: How to use this dashboard
B4: 1. On the Overview sheet, choose a Year and a Month (or "All") in the navy header. KPIs, charts and tables update; ↑/↓ compares with the previous month or year.
B5: 2. Click the sidebar (Overview, Sales, Products, Customers, Orders) to jump between pages. Each page has a "Back to Overview" link.
B6: 3. Add new orders at the bottom of the Orders sheet (an Excel table — keep it sorted by date). Type only the blue columns and the text columns; the formula columns fill themselves.
B7: 4. The Calc sheet holds the helper formulas behind the charts — no need to edit it.
B9: Definitions: Sales = qty × unit price · Profit = sales − qty × unit cost · Total customers = distinct customers who ordered in the period.
B10: Crestview Retail Co. is a fictional company; all figures are demo data. Works in Excel 2010 or later, Excel for the web and LibreOffice. No macros.
